I'm sorry, but an uncaught exception occurred.

While running game code:
  File "game/second_task.rpy", line 3, in script call
    call show_customer("gui/nvl.png", "Котик-Ресторатор", "#ec043d")
  File "game/first_task.rpy", line 1, in script
    label show_customer(picture, name, color):
TypeError: Too many arguments in call (expected 3, got 4).

-- Full Traceback ------------------------------------------------------------

Full traceback:
  File "game/second_task.rpy", line 3, in script call
    call show_customer("gui/nvl.png", "Котик-Ресторатор", "#ec043d")
  File "game/first_task.rpy", line 1, in script
    label show_customer(picture, name, color):
  File "E:\renpy\renpy-8.0.3-sdk\renpy\ast.py", line 1072, in execute
    values = apply_arguments(self.parameters, renpy.store._args, renpy.store._kwargs)
  File "E:\renpy\renpy-8.0.3-sdk\renpy\ast.py", line 294, in apply_arguments
    return parameters.apply(args, kwargs, ignore_errors)
  File "E:\renpy\renpy-8.0.3-sdk\renpy\ast.py", line 248, in apply
    raise TypeError(
TypeError: Too many arguments in call (expected 3, got 4).

Windows-10-10.0.17763 AMD64
Ren'Py 8.0.3.22090809
Пушистые IT 0.0
Tue Nov 29 00:29:27 2022
